<?xml version="1.0"?>
<robot xmlns:xacro="http://www.ros.org/wiki/xacro">

  <link
    name="base_link">
    <inertial>
      <origin
        xyz="0.00088931 1.518E-10 0.022426"
        rpy="0 0 0" />
      <mass
        value="0.093992" />
      <inertia
        ixx="0.00011412"
        ixy="1.977E-13"
        ixz="-1.3528E-06"
        iyy="0.00012443"
        iyz="1.9115E-13"
        izz="0.00019777" />
    </inertial>
    <visual>
      <origin
        xyz="0 0 0"
        rpy="0 0 0" />
      <geometry>
        <mesh
          filename="package://robot_arm/meshes/base_link.STL" />
      </geometry>
      <material
        name="">
        <color
          rgba="1 1 1 1" />
      </material>
    </visual>
    <collision>
      <origin
        xyz="0 0 0"
        rpy="0 0 0" />
      <geometry>
        <mesh
          filename="package://robot_arm/meshes/base_link.STL" />
      </geometry>
    </collision>
  </link>

   <link
    name="rotating_waste_link">
    <inertial>
      <origin
        xyz="-0.0070576 -1.0381E-07 0.019423"
        rpy="0 0 0" />
      <mass
        value="0.091516" />
      <inertia
        ixx="7.8818E-05"
        ixy="-2.8268E-10"
        ixz="8.1273E-06"
        iyy="6.8276E-05"
        iyz="6.7942E-11"
        izz="7.2109E-05" />
    </inertial>
    <visual>
      <origin
        xyz="0 0 0"
        rpy="0 0 0" />
      <geometry>
        <mesh
          filename="package://robot_arm/meshes/rotating_waste_link.STL" />
      </geometry>
      <material
        name="">
        <color
          rgba="1 1 1 1" />
      </material>
    </visual>
    <collision>
      <origin
        xyz="0 0 0"
        rpy="0 0 0" />
      <geometry>
        <mesh
          filename="package://robot_arm/meshes/rotating_waste_link.STL" />
      </geometry>
    </collision>
  </link>

  <joint
    name="base_rotating_waste_joint"
    type="revolute">
    <origin
      xyz="0 0 0.05"
      rpy="0 0 0" />
    <parent
      link="base_link" />
    <child
      link="rotating_waste_link" />
    <axis
      xyz="0 0 1" />
    <limit
      lower="0"
      upper="3.14"
      effort="200"
      velocity="2" />
  </joint>

   <link
    name="arm1_link">
    <inertial>
      <origin
        xyz="0.00631836393428441 0.00457630250829717 0.0698502612146547"
        rpy="0 0 0" />
      <mass
        value="0.140952853784722" />
      <inertia
        ixx="0.000440416626025168"
        ixy="-1.98721405209177E-11"
        ixz="-2.90833471708738E-12"
        iyy="0.000419628031992997"
        iyz="-2.54311534936983E-05"
        izz="3.31281769441693E-05" />
    </inertial>
    <visual>
      <origin
        xyz="0 0 0"
        rpy="0 0 0" />
      <geometry>
        <mesh
          filename="package://robot_arm/meshes/arm1_link.STL" />
      </geometry>
      <material
        name="">
        <color
          rgba="1 1 1 1" />
      </material>
    </visual>
    <collision>
      <origin
        xyz="0 0 0"
        rpy="0 0 0" />
      <geometry>
        <mesh
          filename="package://robot_arm/meshes/arm1_link.STL" />
      </geometry>
    </collision>
  </link>

  <joint
    name="rotating_waste_arm1_joint"
    type="revolute">
    <origin
      xyz="0.0015 0 0.04355"
      rpy="0 0 0" />
    <parent
      link="rotating_waste_link" />
    <child
      link="arm1_link" />
    <axis
      xyz="-1 0 0" />
    <limit
      lower="-1.57"
      upper="1.57"
      effort="300"
      velocity="2" />
  </joint>

  <link
    name="arm2_link">
    <inertial>
      <origin
        xyz="-0.00880357814701982 -0.00216767735851138 0.0625599808566242"
        rpy="0 0 0" />
      <mass
        value="0.0679899973206678" />
      <inertia
        ixx="6.08668610842258E-05"
        ixy="3.18721361237652E-08"
        ixz="-7.99265437177903E-07"
        iyy="5.65315919976104E-05"
        iyz="1.72686317681534E-06"
        izz="1.18089388202385E-05" />
    </inertial>
    <visual>
      <origin
        xyz="0 0 0"
        rpy="0 0 0" />
      <geometry>
        <mesh
          filename="package://robot_arm/meshes/arm2_link.STL" />
      </geometry>
      <material
        name="">
        <color
          rgba="0.627450980392157 0.627450980392157 0.627450980392157 1" />
      </material>
    </visual>
    <collision>
      <origin
        xyz="0 0 0"
        rpy="0 0 0" />
      <geometry>
        <mesh
          filename="package://robot_arm/meshes/arm2_link.STL" />
      </geometry>
    </collision>
  </link>
  <joint
    name="arm1_arm2_joint"
    type="revolute">
    <origin
      xyz="0 0.0091527 0.1397"
      rpy="0 0 0" />
    <parent
      link="arm1_link" />
    <child
      link="arm2_link" />
    <axis
      xyz="1 0 0" />
    <limit
      lower="-1.572"
      upper="1.572"
      effort="300"
      velocity="2" />
  </joint>

  <link
    name="gripper_base_link">
    <inertial>
      <origin
        xyz="-0.0086045 -0.0047925 0.024485"
        rpy="0 0 0" />
      <mass
        value="0.015888" />
      <inertia
        ixx="4.9763E-06"
        ixy="-1.0216E-08"
        ixz="5.5705E-07"
        iyy="6.3729E-06"
        iyz="8.4747E-07"
        izz="2.6359E-06" />
    </inertial>
    <visual>
      <origin
        xyz="0 0 0"
        rpy="0 0 0" />
      <geometry>
        <mesh
          filename="package://robot_arm/meshes/gripper_base_link.STL" />
      </geometry>
      <material
        name="">
        <color
          rgba="1 1 1 1" />
      </material>
    </visual>
    <collision>
      <origin
        xyz="0 0 0"
        rpy="0 0 0" />
      <geometry>
        <mesh
          filename="package://robot_arm/meshes/gripper_base_link.STL" />
      </geometry>
    </collision>
  </link>
  <joint
    name="arm2_gripper_base_joint"
    type="revolute">
    <origin
      xyz="0.011 -0.0039062 0.11959"
      rpy="0 0 0" />
    <parent
      link="arm2_link" />
    <child
      link="gripper_base_link" />
    <axis
      xyz="1 0 0" />
    <limit
      lower="-1.57"
      upper="1.57"
      effort="200"
      velocity="2" />
  </joint>

  <link
    name="left_gear_link">
    <inertial>
      <origin
        xyz="-0.000416201264684057 0.00225628206764544 0.00726342155223458"
        rpy="0 0 0" />
      <mass
        value="0.00288097977011737" />
      <inertia
        ixx="4.58702443643956E-07"
        ixy="2.17136633214979E-09"
        ixz="6.07780555610504E-08"
        iyy="5.52241597953508E-07"
        iyz="-1.31901969283621E-08"
        izz="1.04781150402433E-07" />
    </inertial>
    <visual>
      <origin
        xyz="0 0 0"
        rpy="0 0 0" />
      <geometry>
        <mesh
          filename="package://robot_arm/meshes/left_gear_link.STL" />
      </geometry>
      <material
        name="">
        <color
          rgba="1 1 1 1" />
      </material>
    </visual>
    <collision>
      <origin
        xyz="0 0 0"
        rpy="0 0 0" />
      <geometry>
        <mesh
          filename="package://robot_arm/meshes/left_gear_link.STL" />
      </geometry>
    </collision>
  </link>
  <joint
    name="gripper_base_left_gear_joint"
    type="revolute">
    <origin
      xyz="-0.02295 -0.018135 0.0302"
      rpy="0 0 0" />
    <parent
      link="gripper_base_link" />
    <child
      link="left_gear_link" />
    <axis
      xyz="0 1 0" />
    <limit
      lower="-1.57"
      upper="1.57"
      effort="200"
      velocity="2" />
  </joint>

  <link
    name="right_gear_link">
    <inertial>
      <origin
        xyz="-0.000511366230434651 0.00299999999999997 0.00558778456902781"
        rpy="0 0 0" />
      <mass
        value="0.00404166832548351" />
      <inertia
        ixx="5.63449978901378E-07"
        ixy="2.12482258863504E-23"
        ixz="-2.09627300327499E-08"
        iyy="6.84276691264749E-07"
        iyz="1.73661663718213E-23"
        izz="1.45076722316272E-07" />
    </inertial>
    <visual>
      <origin
        xyz="0 0 0"
        rpy="0 0 0" />
      <geometry>
        <mesh
          filename="package://robot_arm/meshes/right_gear_link.STL" />
      </geometry>
      <material
        name="">
        <color
          rgba="1 1 1 1" />
      </material>
    </visual>
    <collision>
      <origin
        xyz="0 0 0"
        rpy="0 0 0" />
      <geometry>
        <mesh
          filename="package://robot_arm/meshes/right_gear_link.STL" />
      </geometry>
    </collision>
  </link>
  <joint
    name="gripper_base_right_gear_joint"
    type="revolute">
    <origin
      xyz="0.00395 -0.018135 0.0302"
      rpy="0 0 0" />
    <parent
      link="gripper_base_link" />
    <child
      link="right_gear_link" />
    <axis
      xyz="0 1 0" />
    <limit
      lower="-1.57"
      upper="1.57"
      effort="200"
      velocity="2" />
    <mimic
      joint="gripper_base_left_gear_joint"
      multiplier="-1"
      offset="0" />
  </joint>




</robot> 